<?xml version="1.0" ?>
<sdf version='1.6'>
  <model name='FlexRobot_v1'>
    <link name='FrontBody'>
      <pose frame=''>0 0 0 0 -0 0</pose>
      <inertial>
        <pose frame=''>-0.55658 0.10246 0.35766 0 -0 0</pose>
        <mass>4.5059</mass>
        <inertia>
          <ixx>0.051537</ixx>
          <ixy>1.0077e-05</ixy>
          <ixz>0.00011737</ixz>
          <iyy>0.013909</iyy>
          <iyz>-4.4566e-05</iyz>
          <izz>0.054057</izz>
        </inertia>
      </inertial>
      <collision name='FrontBody_collision'>
        <pose frame=''>0 0 0 0 -0 0</pose>
        <geometry>
          <mesh>
            <scale>1 1 1</scale>
            <uri>model://FlexRobot_v1/meshes/FrontBody.STL</uri>
          </mesh>
        </geometry>
      </collision>
      <visual name='FrontBody_visual'>
        <pose frame=''>0 0 0 0 -0 0</pose>
        <geometry>
          <mesh>
            <scale>1 1 1</scale>
            <uri>model://FlexRobot_v1/meshes/FrontBody.STL</uri>
          </mesh>
        </geometry>
      </visual>
    </link>
    <link name='BackBody'>
      <pose frame=''>-0.40775 0.083439 0.36531 0 0 0</pose>
      <inertial>
        <pose frame=''>0.215 0.019021 0.0008 0 -0 0</pose>
        <mass>4.8301</mass>
        <inertia>
          <ixx>0.052001</ixx>
          <ixy>4.9713e-05</ixy>
          <ixz>0.00011769</ixz>
          <iyy>0.021949</iyy>
          <iyz>-1.9983e-05</iyz>
          <izz>0.061678</izz>
        </inertia>
      </inertial>
      <collision name='BackBody_collision'>
        <pose frame=''>0 0 0 0 -0 0</pose>
        <geometry>
          <mesh>
            <scale>1 1 1</scale>
            <uri>model://FlexRobot_v1/meshes/BackBody.STL</uri>
          </mesh>
        </geometry>
      </collision>
      <visual name='BackBody_visual'>
        <pose frame=''>0 0 0 0 -0 0</pose>
        <geometry>
          <mesh>
            <scale>1 1 1</scale>
            <uri>model://FlexRobot_v1/meshes/BackBody.STL</uri>
          </mesh>
        </geometry>
      </visual>
    </link>
    <joint name='BodyJoint' type='revolute'>
      <child>BackBody</child>
      <parent>FrontBody</parent>
      <axis>
        <xyz>0 -1 -0</xyz>
        <limit>
          <lower>-1e+16</lower>
          <upper>1e+16</upper>
        </limit>
        <dynamics>
          <spring_reference>0</spring_reference>
          <spring_stiffness>0</spring_stiffness>
        </dynamics>
        <use_parent_model_frame>1</use_parent_model_frame>
      </axis>
    </joint>
    <link name='RearBodyLeftLeg_Hip'>
      <pose frame=''>-0.17775 0.07246 0.36531 0 0 0</pose>
      <inertial>
        <pose frame=''>0.04503 -0.071534 -0.058122 0 -0 0</pose>
        <mass>0.23878</mass>
        <inertia>
          <ixx>0.00071753</ixx>
          <ixy>-9.7867e-06</ixy>
          <ixz>-0.00048927</ixz>
          <iyy>0.0011216</iyy>
          <iyz>1.2632e-05</iyz>
          <izz>0.00046505</izz>
        </inertia>
      </inertial>
      <collision name='RearBodyLeftLeg_Hip_collision'>
        <pose frame=''>0 0 0 0 -0 0</pose>
        <geometry>
          <mesh>
            <scale>1 1 1</scale>
            <uri>model://FlexRobot_v1/meshes/RearBodyLeftLeg_Hip.STL</uri>
          </mesh>
        </geometry>
      </collision>
      <visual name='RearBodyLeftLeg_Hip_visual'>
        <pose frame=''>0 0 0 0 -0 0</pose>
        <geometry>
          <mesh>
            <scale>1 1 1</scale>
            <uri>model://FlexRobot_v1/meshes/RearBodyLeftLeg_Hip.STL</uri>
          </mesh>
        </geometry>
      </visual>
    </link>
    <joint name='RearBodyLeftLeg_Hip_Joint' type='revolute'>
      <child>RearBodyLeftLeg_Hip</child>
      <parent>BackBody</parent>
      <axis>
        <xyz>0 -1 -0</xyz>
        <limit>
          <lower>-1e+16</lower>
          <upper>1e+16</upper>
        </limit>
        <dynamics>
          <spring_reference>0</spring_reference>
          <spring_stiffness>0</spring_stiffness>
        </dynamics>
        <use_parent_model_frame>1</use_parent_model_frame>
      </axis>
    </joint>
    <link name='RearBodyLeftLeg_Knee'>
      <pose frame=''>-0.07425 -0.0195 0.23171 0 0 0</pose>
      <inertial>
        <pose frame=''>0.025803 0.0195 -0.032369 0 -0 0</pose>
        <mass>0.092493</mass>
        <inertia>
          <ixx>0.00043795</ixx>
          <ixy>1.0876e-12</ixy>
          <ixz>-6.9646e-05</ixz>
          <iyy>0.00049392</iyy>
          <iyz>-1.9594e-12</iyz>
          <izz>6.4686e-05</izz>
        </inertia>
      </inertial>
      <collision name='RearBodyLeftLeg_Knee_collision'>
        <pose frame=''>0 0 0 0 -0 0</pose>
        <geometry>
          <mesh>
            <scale>1 1 1</scale>
            <uri>model://FlexRobot_v1/meshes/RearBodyLeftLeg_Knee.STL</uri>
          </mesh>
        </geometry>
      </collision>
      <visual name='RearBodyLeftLeg_Knee_visual'>
        <pose frame=''>0 0 0 0 -0 0</pose>
        <geometry>
          <mesh>
            <scale>1 1 1</scale>
            <uri>model://FlexRobot_v1/meshes/RearBodyLeftLeg_Knee.STL</uri>
          </mesh>
        </geometry>
      </visual>
    </link>
    <joint name='RearBodyLeftLeg_Knee' type='revolute'>
      <child>RearBodyLeftLeg_Knee</child>
      <parent>RearBodyLeftLeg_Hip</parent>
      <axis>
        <xyz>0 -1 -0</xyz>
        <limit>
          <lower>-1e+16</lower>
          <upper>1e+16</upper>
        </limit>
        <dynamics>
          <spring_reference>0</spring_reference>
          <spring_stiffness>0</spring_stiffness>
        </dynamics>
        <use_parent_model_frame>1</use_parent_model_frame>
      </axis>
    </joint>
    <link name='RearBodyRightLeg_Hip'>
      <pose frame=''>-0.17775 0.07246 0.36531 0 0 0</pose>
      <inertial>
        <pose frame=''>0.043413 0.13153 -0.059402 0 -0 0</pose>
        <mass>0.23878</mass>
        <inertia>
          <ixx>0.00074488</ixx>
          <ixy>9.558e-06</ixy>
          <ixz>-0.00048056</ixz>
          <iyy>0.0011198</iyy>
          <iyz>-1.2953e-05</iyz>
          <izz>0.00043593</izz>
        </inertia>
      </inertial>
      <collision name='RearBodyRightLeg_Hip_collision'>
        <pose frame=''>0 0 0 0 -0 0</pose>
        <geometry>
          <mesh>
            <scale>1 1 1</scale>
            <uri>model://FlexRobot_v1/meshes/RearBodyRightLeg_Hip.STL</uri>
          </mesh>
        </geometry>
      </collision>
      <visual name='RearBodyRightLeg_Hip_visual'>
        <pose frame=''>0 0 0 0 -0 0</pose>
        <geometry>
          <mesh>
            <scale>1 1 1</scale>
            <uri>model://FlexRobot_v1/meshes/RearBodyRightLeg_Hip.STL</uri>
          </mesh>
        </geometry>
      </visual>
    </link>
    <joint name='RearBodyRightLeg_Hip' type='revolute'>
      <child>RearBodyRightLeg_Hip</child>
      <parent>BackBody</parent>
      <axis>
        <xyz>0 -1 -0</xyz>
        <limit>
          <lower>-1e+16</lower>
          <upper>1e+16</upper>
        </limit>
        <dynamics>
          <spring_reference>0</spring_reference>
          <spring_stiffness>0</spring_stiffness>
        </dynamics>
        <use_parent_model_frame>1</use_parent_model_frame>
      </axis>
    </joint>
    <link name='RearBodyRightLeg_Knee'>
      <pose frame=''>-0.078096 0.18542 0.22882 0 0 0</pose>
      <inertial>
        <pose frame=''>0.02487 0.0195 -0.033091 0 -0 0</pose>
        <mass>0.092493</mass>
        <inertia>
          <ixx>0.00044162</ixx>
          <ixy>1.0346e-12</ixy>
          <ixz>-5.8899e-05</ixz>
          <iyy>0.00049392</iyy>
          <iyz>-2.005e-12</iyz>
          <izz>6.1022e-05</izz>
        </inertia>
      </inertial>
      <collision name='RearBodyRightLeg_Knee_collision'>
        <pose frame=''>0 0 0 0 -0 0</pose>
        <geometry>
          <mesh>
            <scale>1 1 1</scale>
            <uri>model://FlexRobot_v1/meshes/RearBodyRightLeg_Knee.STL</uri>
          </mesh>
        </geometry>
      </collision>
      <visual name='RearBodyRightLeg_Knee_visual'>
        <pose frame=''>0 0 0 0 -0 0</pose>
        <geometry>
          <mesh>
            <scale>1 1 1</scale>
            <uri>model://FlexRobot_v1/meshes/RearBodyRightLeg_Knee.STL</uri>
          </mesh>
        </geometry>
      </visual>
    </link>
    <joint name='RearBodyRightLeg_Knee' type='revolute'>
      <child>RearBodyRightLeg_Knee</child>
      <parent>RearBodyRightLeg_Hip</parent>
      <axis>
        <xyz>0 -1 -0</xyz>
        <limit>
          <lower>-1e+16</lower>
          <upper>1e+16</upper>
        </limit>
        <dynamics>
          <spring_reference>0</spring_reference>
          <spring_stiffness>0</spring_stiffness>
        </dynamics>
        <use_parent_model_frame>1</use_parent_model_frame>
      </axis>
    </joint>
    <link name='FrontLeftLeg_Hip'>
      <pose frame=''>-0.56254 0.07246 0.35731 0 0 0</pose>
      <inertial>
        <pose frame=''>-0.024699 -0.071534 -0.069252 0 -0 0</pose>
        <mass>0.23878</mass>
        <inertia>
          <ixx>0.00098254</ixx>
          <ixy>5.3675e-06</ixy>
          <ixz>0.00031976</ixz>
          <iyy>0.0011216</iyy>
          <iyz>1.5051e-05</iyz>
          <izz>0.00020005</izz>
        </inertia>
      </inertial>
      <collision name='FrontLeftLeg_Hip_collision'>
        <pose frame=''>0 0 0 0 -0 0</pose>
        <geometry>
          <mesh>
            <scale>1 1 1</scale>
            <uri>model://FlexRobot_v1/meshes/FrontLeftLeg_Hip.STL</uri>
          </mesh>
        </geometry>
      </collision>
      <visual name='FrontLeftLeg_Hip_visual'>
        <pose frame=''>0 0 0 0 -0 0</pose>
        <geometry>
          <mesh>
            <scale>1 1 1</scale>
            <uri>model://FlexRobot_v1/meshes/FrontLeftLeg_Hip.STL</uri>
          </mesh>
        </geometry>
      </visual>
    </link>
    <joint name='FrontLeftLeg_Hip_Joint' type='revolute'>
      <child>FrontLeftLeg_Hip</child>
      <parent>FrontBody</parent>
      <axis>
        <xyz>0 -1 -0</xyz>
        <limit>
          <lower>-1e+16</lower>
          <upper>1e+16</upper>
        </limit>
        <dynamics>
          <spring_reference>0</spring_reference>
          <spring_stiffness>0</spring_stiffness>
        </dynamics>
        <use_parent_model_frame>1</use_parent_model_frame>
      </axis>
    </joint>
    <link name='FrontLeftLeg_Knee'>
      <pose frame=''>-0.619311 -0.0195 0.19813 0 0 0</pose>
      <inertial>
        <pose frame=''>-0.013364 0.0195 -0.039178 0 -0 0</pose>
        <mass>0.092493</mass>
        <inertia>
          <ixx>0.00023629</ixx>
          <ixy>-9.7923e-13</ixy>
          <ixz>0.00019864</ixz>
          <iyy>0.00049392</iyy>
          <iyz>-1.7031e-12</iyz>
          <izz>0.00026635</izz>
        </inertia>
      </inertial>
      <collision name='FrontLeftLeg_Knee_collision'>
        <pose frame=''>0 0 0 0 -0 0</pose>
        <geometry>
          <mesh>
            <scale>1 1 1</scale>
            <uri>model://FlexRobot_v1/meshes/FrontLeftLeg_Knee.STL</uri>
          </mesh>
        </geometry>
      </collision>
      <visual name='FrontLeftLeg_Knee_visual'>
        <pose frame=''>0 0 0 0 -0 0</pose>
        <geometry>
          <mesh>
            <scale>1 1 1</scale>
            <uri>model://FlexRobot_v1/meshes/FrontLeftLeg_Knee.STL</uri>
          </mesh>
        </geometry>
      </visual>
    </link>
    <joint name='FrontLeftLeg_Knee_joint' type='revolute'>
      <child>FrontLeftLeg_Knee</child>
      <parent>FrontLeftLeg_Hip</parent>
      <axis>
        <xyz>0 -1 -0</xyz>
        <limit>
          <lower>-1e+16</lower>
          <upper>1e+16</upper>
        </limit>
        <dynamics>
          <spring_reference>0</spring_reference>
          <spring_stiffness>0</spring_stiffness>
        </dynamics>
        <use_parent_model_frame>1</use_parent_model_frame>
      </axis>
    </joint>
    <link name='FrontRightLeg_Hip'>
      <pose frame=''>-0.56254 0.07246 0.35731 0 0 0</pose>
      <inertial>
        <pose frame=''>-0.024603 0.13153 -0.06934 0 -0 0</pose>
        <mass>0.23878</mass>
        <inertia>
          <ixx>0.00098151</ixx>
          <ixy>-5.3134e-06</ixy>
          <ixz>0.00031913</ixz>
          <iyy>0.0011198</iyy>
          <iyz>-1.5195e-05</iyz>
          <izz>0.0001993</izz>
        </inertia>
      </inertial>
      <collision name='FrontRightLeg_Hip_collision'>
        <pose frame=''>0 0 0 0 -0 0</pose>
        <geometry>
          <mesh>
            <scale>1 1 1</scale>
            <uri>model://FlexRobot_v1/meshes/FrontRightLeg_Hip.STL</uri>
          </mesh>
        </geometry>
      </collision>
      <visual name='FrontRightLeg_Hip_visual'>
        <pose frame=''>0 0 0 0 -0 0</pose>
        <geometry>
          <mesh>
            <scale>1 1 1</scale>
            <uri>model://FlexRobot_v1/meshes/FrontRightLeg_Hip.STL</uri>
          </mesh>
        </geometry>
      </visual>
    </link>
    <joint name='FrontRightLeg_Hip_Joint' type='revolute'>
      <child>FrontRightLeg_Hip</child>
      <parent>FrontBody</parent>
      <axis>
        <xyz>0 -1 -0</xyz>
        <limit>
          <lower>-1e+16</lower>
          <upper>1e+16</upper>
        </limit>
        <dynamics>
          <spring_reference>0</spring_reference>
          <spring_stiffness>0</spring_stiffness>
        </dynamics>
        <use_parent_model_frame>1</use_parent_model_frame>
      </axis>
    </joint>
    <link name='FrontRightLeg_Knee'>
      <pose frame=''>-0.619129 0.18492 0.19807 0 0 0</pose>
      <inertial>
        <pose frame=''>-0.01332 0.02 -0.039193 0 -0 0</pose>
        <mass>0.092493</mass>
        <inertia>
          <ixx>0.00023674</ixx>
          <ixy>-9.7744e-13</ixy>
          <ixz>0.00019867</ixz>
          <iyy>0.00049392</iyy>
          <iyz>-1.7044e-12</iyz>
          <izz>0.00026589</izz>
        </inertia>
      </inertial>
      <collision name='FrontRightLeg_Knee_collision'>
        <pose frame=''>0 0 0 0 -0 0</pose>
        <geometry>
          <mesh>
            <scale>1 1 1</scale>
            <uri>model://FlexRobot_v1/meshes/FrontRightLeg_Knee.STL</uri>
          </mesh>
        </geometry>
      </collision>
      <visual name='FrontRightLeg_Knee_visual'>
        <pose frame=''>0 0 0 0 -0 0</pose>
        <geometry>
          <mesh>
            <scale>1 1 1</scale>
            <uri>model://FlexRobot_v1/meshes/FrontRightLeg_Knee.STL</uri>
          </mesh>
        </geometry>
      </visual>
    </link>
    <joint name='FrontRightLeg_Knee_Joint' type='revolute'>
      <child>FrontRightLeg_Knee</child>
      <parent>FrontRightLeg_Hip</parent>
      <axis>
        <xyz>0 -1 -0</xyz>
        <limit>
          <lower>-1e+16</lower>
          <upper>1e+16</upper>
        </limit>
        <dynamics>
          <spring_reference>0</spring_reference>
          <spring_stiffness>0</spring_stiffness>
        </dynamics>
        <use_parent_model_frame>1</use_parent_model_frame>
      </axis>
    </joint>
  </model>
</sdf>
